Workbook

Sheet EXAMES
A1: ANO 1
A2: Ticket | B2: 497 | D2: MÊS | E2: FATURAMENTO | F2: CUSTO DIRETO | G2: IMPOSTO | H2: LUCRO LÍQUIDO | J2: CLIENTES
A3: CUSTO PLATAFORMA | B3: 89.9 | D3: 1 | E3: =$B$2*J3 -> 994 | F3: =($B$3*J3)+$B$4 -> 2554.8 | G3: =E3*0.1 -> 99.4 | H3: =E3-F3-G3 -> -1660.2 | J3: 2
A4: CUSTO STOP LOSS | B4: =B6*B7/12 -> 2375 | D4: 2 | E4: =$B$2*J4 -> 1491 | F4: =($B$3*J4)+$B$4 -> 2644.7 | G4: =E4*0.1 -> 149.1 | H4: =E4-F4-G4 -> -1302.8 | J4: 3
A5: TRADERS ATIVOS | B5: 5 | D5: 3 | E5: =$B$2*J5 -> 2485 | F5: =($B$3*J5)+$B$4 -> 2824.5 | G5: =E5*0.1 -> 248.5 | H5: =E5-F5-G5 -> -588 | J5: 5
A6: TRADERS STOP LOSS | B6: 15 | D6: 4 | E6: =$B$2*J6 -> 2982 | F6: =($B$3*J6)+$B$4 -> 2914.4 | G6: =E6*0.1 -> 298.2 | H6: =E6-F6-G6 -> -230.6 | J6: 6
A7: STOP LOSS | B7: 1900 | D7: 5 | E7: =$B$2*J7 -> 3479 | F7: =($B$3*J7)+$B$4 -> 3004.3 | G7: =E7*0.1 -> 347.9 | H7: =E7-F7-G7 -> 126.8 | J7: 7
D8: 6 | E8: =$B$2*J8 -> 3976 | F8: =($B$3*J8)+$B$4 -> 3094.2 | G8: =E8*0.1 -> 397.6 | H8: =E8-F8-G8 -> 484.2 | J8: 8
A9: TRADERS APROVADOS | B9: 20 | D9: 7 | E9: =$B$2*J9 -> 4473 | F9: =($B$3*J9)+$B$4 -> 3184.1 | G9: =E9*0.1 -> 447.3 | H9: =E9-F9-G9 -> 841.6 | J9: 9
D10: 8 | E10: =$B$2*J10 -> 4970 | F10: =($B$3*J10)+$B$4 -> 3274 | G10: =E10*0.1 -> 497 | H10: =E10-F10-G10 -> 1199 | J10: 10
D11: 9 | E11: =$B$2*J11 -> 5467 | F11: =($B$3*J11)+$B$4 -> 3363.9 | G11: =E11*0.1 -> 546.7 | H11: =E11-F11-G11 -> 1556.4 | J11: 11
D12: 10 | E12: =$B$2*J12 -> 5964 | F12: =($B$3*J12)+$B$4 -> 3453.8 | G12: =E12*0.1 -> 596.4 | H12: =E12-F12-G12 -> 1913.8 | J12: 12
D13: 11 | E13: =$B$2*J13 -> 6461 | F13: =($B$3*J13)+$B$4 -> 3543.7 | G13: =E13*0.1 -> 646.1 | H13: =E13-F13-G13 -> 2271.2 | J13: 13
D14: 12 | E14: =$B$2*J14 -> 6958 | F14: =($B$3*J14)+$B$4 -> 3633.6 | G14: =E14*0.1 -> 695.8 | H14: =E14-F14-G14 -> 2628.6 | J14: 14
E15: =SUM(E3:E14) -> 49700 | F15: =SUM(F3:F14) -> 37490 | G15: =SUM(G3:G14) -> 4970 | H15: =SUM(H3:H14) -> 7240 | J15: =SUM(J3:J14) -> 100
A18: ANO 2
A19: Ticket | B19: 497 | D19: MÊS | E19: FATURAMENTO | F19: CUSTO DIRETO | G19: IMPOSTO | H19: LUCRO LÍQUIDO | J19: CLIENTES
A20: CUSTO PLATAFORMA | B20: 89.9 | D20: 1 | E20: =$B$19*J20 -> 2485 | F20: =($B$20*J20)+$B$21 -> 3299.5 | G20: =E20*0.1 -> 248.5 | H20: =E20-F20-G20 -> -1063 | J20: 5
A21: CUSTO STOP LOSS | B21: =B23*B24/12 -> 2850 | D21: 2 | E21: =$B$19*J21 -> 2982 | F21: =($B$20*J21)+$B$21 -> 3389.4 | G21: =E21*0.1 -> 298.2 | H21: =E21-F21-G21 -> -705.6 | J21: 6
A22: TRADERS ATIVOS | B22: 6 | D22: 3 | E22: =$B$19*J22 -> 3479 | F22: =($B$20*J22)+$B$21 -> 3479.3 | G22: =E22*0.1 -> 347.9 | H22: =E22-F22-G22 -> -348.2 | J22: 7
A23: TRADERS STOP LOSS | B23: 18 | D23: 4 | E23: =$B$19*J23 -> 3976 | F23: =($B$20*J23)+$B$21 -> 3569.2 | G23: =E23*0.1 -> 397.6 | H23: =E23-F23-G23 -> 9.2 | J23: 8
A24: STOP LOSS | B24: 1900 | D24: 5 | E24: =$B$19*J24 -> 4473 | F24: =($B$20*J24)+$B$21 -> 3659.1 | G24: =E24*0.1 -> 447.3 | H24: =E24-F24-G24 -> 366.6 | J24: 9
D25: 6 | E25: =$B$19*J25 -> 4970 | F25: =($B$20*J25)+$B$21 -> 3749 | G25: =E25*0.1 -> 497 | H25: =E25-F25-G25 -> 724 | J25: 10
A26: TRADERS APROVADOS | B26: 24 | D26: 7 | E26: =$B$19*J26 -> 4970 | F26: =($B$20*J26)+$B$21 -> 3749 | G26: =E26*0.1 -> 497 | H26: =E26-F26-G26 -> 724 | J26: 10
D27: 8 | E27: =$B$19*J27 -> 5467 | F27: =($B$20*J27)+$B$21 -> 3838.9 | G27: =E27*0.1 -> 546.7 | H27: =E27-F27-G27 -> 1081.4 | J27: 11
D28: 9 | E28: =$B$19*J28 -> 5964 | F28: =($B$20*J28)+$B$21 -> 3928.8 | G28: =E28*0.1 -> 596.4 | H28: =E28-F28-G28 -> 1438.8 | J28: 12
D29: 10 | E29: =$B$19*J29 -> 6461 | F29: =($B$20*J29)+$B$21 -> 4018.7 | G29: =E29*0.1 -> 646.1 | H29: =E29-F29-G29 -> 1796.2 | J29: 13
D30: 11 | E30: =$B$19*J30 -> 6958 | F30: =($B$20*J30)+$B$21 -> 4108.6 | G30: =E30*0.1 -> 695.8 | H30: =E30-F30-G30 -> 2153.6 | J30: 14
D31: 12 | E31: =$B$19*J31 -> 7455 | F31: =($B$20*J31)+$B$21 -> 4198.5 | G31: =E31*0.1 -> 745.5 | H31: =E31-F31-G31 -> 2511 | J31: 15
E32: =SUM(E20:E31) -> 59640 | F32: =SUM(F20:F31) -> 44988 | G32: =SUM(G20:G31) -> 5964 | H32: =SUM(H20:H31) -> 8688 | J32: =SUM(J20:J31) -> 120
A35: ANO 3
A36: Ticket | B36: 497 | D36: MÊS | E36: FATURAMENTO | F36: CUSTO DIRETO | G36: IMPOSTO | H36: LUCRO LÍQUIDO | J36: CLIENTES
A37: CUSTO PLATAFORMA | B37: 89.9 | D37: 1 | E37: =$B$36*J37 -> 3479 | F37: =($B$37*J37)+$B$38 -> 3954.3 | G37: =E37*0.1 -> 347.9 | H37: =E37-F37-G37 -> -823.2 | J37: 7
A38: CUSTO STOP LOSS | B38: =B40*B41/12 -> 3325 | D38: 2 | E38: =$B$36*J38 -> 3976 | F38: =($B$37*J38)+$B$38 -> 4044.2 | G38: =E38*0.1 -> 397.6 | H38: =E38-F38-G38 -> -465.8 | J38: 8
A39: TRADERS ATIVOS | B39: 7 | D39: 3 | E39: =$B$36*J39 -> 4473 | F39: =($B$37*J39)+$B$38 -> 4134.1 | G39: =E39*0.1 -> 447.3 | H39: =E39-F39-G39 -> -108.4 | J39: 9
A40: TRADERS STOP LOSS | B40: 21 | D40: 4 | E40: =$B$36*J40 -> 4970 | F40: =($B$37*J40)+$B$38 -> 4224 | G40: =E40*0.1 -> 497 | H40: =E40-F40-G40 -> 249 | J40: 10
A41: STOP LOSS | B41: 1900 | D41: 5 | E41: =$B$36*J41 -> 5467 | F41: =($B$37*J41)+$B$38 -> 4313.9 | G41: =E41*0.1 -> 546.7 | H41: =E41-F41-G41 -> 606.4 | J41: 11
D42: 6 | E42: =$B$36*J42 -> 5964 | F42: =($B$37*J42)+$B$38 -> 4403.8 | G42: =E42*0.1 -> 596.4 | H42: =E42-F42-G42 -> 963.8 | J42: 12
A43: TRADERS APROVADOS | B43: 28 | D43: 7 | E43: =$B$36*J43 -> 5964 | F43: =($B$37*J43)+$B$38 -> 4403.8 | G43: =E43*0.1 -> 596.4 | H43: =E43-F43-G43 -> 963.8 | J43: 12
D44: 8 | E44: =$B$36*J44 -> 6461 | F44: =($B$37*J44)+$B$38 -> 4493.7 | G44: =E44*0.1 -> 646.1 | H44: =E44-F44-G44 -> 1321.2 | J44: 13
...

Sheet PLATAFORMAS
A1: ANO 1
A2: Ticket | B2: 99 | D2: MÊS | E2: FATURAMENTO | F2: CUSTO DIRETO | G2: LUCRO LÍQUIDO | I2: CLIENTES
A3: CUSTO PLATAFORMA | B3: 89.9 | D3: 1 | E3: =$B$2*I3 -> 0 | F3: =$B$3*I3 -> 0 | G3: =E3-F3 -> 0 | I3: 0
A4: TRADERS ATIVOS | B4: 5 | D4: 2 | E4: =$B$2*I4 -> 0 | F4: =$B$3*I4 -> 0 | G4: =E4-F4 -> 0 | I4: 0
D5: 3 | E5: =$B$2*I5 -> 99 | F5: =$B$3*I5 -> 89.9 | G5: =E5-F5 -> 9.1 | I5: 1
D6: 4 | E6: =$B$2*I6 -> 99 | F6: =$B$3*I6 -> 89.9 | G6: =E6-F6 -> 9.1 | I6: 1
D7: 5 | E7: =$B$2*I7 -> 198 | F7: =$B$3*I7 -> 179.8 | G7: =E7-F7 -> 18.2 | I7: 2
D8: 6 | E8: =$B$2*I8 -> 198 | F8: =$B$3*I8 -> 179.8 | G8: =E8-F8 -> 18.2 | I8: 2
D9: 7 | E9: =$B$2*I9 -> 297 | F9: =$B$3*I9 -> 269.7 | G9: =E9-F9 -> 27.3 | I9: 3
D10: 8 | E10: =$B$2*I10 -> 297 | F10: =$B$3*I10 -> 269.7 | G10: =E10-F10 -> 27.3 | I10: 3
D11: 9 | E11: =$B$2*I11 -> 396 | F11: =$B$3*I11 -> 359.6 | G11: =E11-F11 -> 36.4 | I11: 4
D12: 10 | E12: =$B$2*I12 -> 396 | F12: =$B$3*I12 -> 359.6 | G12: =E12-F12 -> 36.4 | I12: 4
D13: 11 | E13: =$B$2*I13 -> 495 | F13: =$B$3*I13 -> 449.5 | G13: =E13-F13 -> 45.5 | I13: 5
D14: 12 | E14: =$B$2*I14 -> 495 | F14: =$B$3*I14 -> 449.5 | G14: =E14-F14 -> 45.5 | I14: 5
E15: =SUM(E3:E14) -> 2970 | F15: =SUM(F3:F14) -> 2697 | G15: =SUM(G3:G14) -> 273
A18: ANO 2
A19: Ticket | B19: 99 | D19: MÊS | E19: FATURAMENTO | F19: CUSTO DIRETO | G19: LUCRO LÍQUIDO | I19: CLIENTES
A20: CUSTO PLATAFORMA | B20: 89.9 | D20: 1 | E20: =$B$19*I20 -> 495 | F20: =$B$20*I20 -> 449.5 | G20: =E20-F20 -> 45.5 | I20: 5
A21: TRADERS ATIVOS | B21: 6 | D21: 2 | E21: =$B$19*I21 -> 594 | F21: =$B$20*I21 -> 539.4 | G21: =E21-F21 -> 54.6 | I21: 6
D22: 3 | E22: =$B$19*I22 -> 693 | F22: =$B$20*I22 -> 629.3 | G22: =E22-F22 -> 63.7 | I22: 7
D23: 4 | E23: =$B$19*I23 -> 693 | F23: =$B$20*I23 -> 629.3 | G23: =E23-F23 -> 63.7 | I23: 7
D24: 5 | E24: =$B$19*I24 -> 792 | F24: =$B$20*I24 -> 719.2 | G24: =E24-F24 -> 72.8 | I24: 8
D25: 6 | E25: =$B$19*I25 -> 792 | F25: =$B$20*I25 -> 719.2 | G25: =E25-F25 -> 72.8 | I25: 8
D26: 7 | E26: =$B$19*I26 -> 891 | F26: =$B$20*I26 -> 809.1 | G26: =E26-F26 -> 81.9 | I26: 9
D27: 8 | E27: =$B$19*I27 -> 891 | F27: =$B$20*I27 -> 809.1 | G27: =E27-F27 -> 81.9 | I27: 9
D28: 9 | E28: =$B$19*I28 -> 990 | F28: =$B$20*I28 -> 899 | G28: =E28-F28 -> 91 | I28: 10
D29: 10 | E29: =$B$19*I29 -> 990 | F29: =$B$20*I29 -> 899 | G29: =E29-F29 -> 91 | I29: 10
D30: 11 | E30: =$B$19*I30 -> 1089 | F30: =$B$20*I30 -> 988.9 | G30: =E30-F30 -> 100.1 | I30: 11
D31: 12 | E31: =$B$19*I31 -> 1089 | F31: =$B$20*I31 -> 988.9 | G31: =E31-F31 -> 100.1 | I31: 11
E32: =SUM(E20:E31) -> 9999 | F32: =SUM(F20:F31) -> 9079.9 | G32: =SUM(G20:G31) -> 919.1
A35: ANO 3
A36: Ticket | B36: 99 | D36: MÊS | E36: FATURAMENTO | F36: CUSTO DIRETO | G36: LUCRO LÍQUIDO | I36: CLIENTES
A37: CUSTO PLATAFORMA | B37: 89.9 | D37: 1 | E37: =$B$36*I37 -> 1188 | F37: =$B$37*I37 -> 1078.8 | G37: =E37-F37 -> 109.2 | I37: 12
A38: TRADERS ATIVOS | B38: 7 | D38: 2 | E38: =$B$36*I38 -> 1287 | F38: =$B$37*I38 -> 1168.7 | G38: =E38-F38 -> 118.3 | I38: 13
D39: 3 | E39: =$B$36*I39 -> 1386 | F39: =$B$37*I39 -> 1258.6 | G39: =E39-F39 -> 127.4 | I39: 14
D40: 4 | E40: =$B$36*I40 -> 1386 | F40: =$B$37*I40 -> 1258.6 | G40: =E40-F40 -> 127.4 | I40: 14
D41: 5 | E41: =$B$36*I41 -> 1485 | F41: =$B$37*I41 -> 1348.5 | G41: =E41-F41 -> 136.5 | I41: 15
D42: 6 | E42: =$B$36*I42 -> 1485 | F42: =$B$37*I42 -> 1348.5 | G42: =E42-F42 -> 136.5 | I42: 15
D43: 7 | E43: =$B$36*I43 -> 1584 | F43: =$B$37*I43 -> 1438.4 | G43: =E43-F43 -> 145.6 | I43: 16
D44: 8 | E44: =$B$36*I44 -> 1584 | F44: =$B$37*I44 -> 1438.4 | G44: =E44-F44 -> 145.6 | I44: 16
...

Sheet CORRETAGEM
A1: ANO 1
A2: Corretagem | B2: 0.3 | D2: MÊS | E2: FATURAMENTO | F2: CUSTO DIRETO | G2: LUCRO LÍQUIDO | I2: CLIENTES
A3: Custo | B3: 0.25 | D3: 1 | E3: =$B$2*$B$7*$B$8*$B$9*$B$10*I3 -> 0 | F3: =$B$3*$B$7*$B$8*$B$9*$B$10*I3 -> 0 | G3: =E3-F3 -> 0 | I3: 0
A4: Lucro Bruto | B4: =B2-B3 -> 0.05 | D4: 2 | E4: =$B$2*$B$7*$B$8*$B$9*$B$10*I4 -> 0 | F4: =$B$3*$B$7*$B$8*$B$9*$B$10*I4 -> 0 | G4: =E4-F4 -> 0 | I4: 0
A5: TRADERS ATIVOS | B5: 5 | D5: 3 | E5: =$B$2*$B$7*$B$8*$B$9*$B$10*I5 -> 324 | F5: =$B$3*$B$7*$B$8*$B$9*$B$10*I5 -> 270 | G5: =E5-F5 -> 54 | I5: 1
D6: 4 | E6: =$B$2*$B$7*$B$8*$B$9*$B$10*I6 -> 324 | F6: =$B$3*$B$7*$B$8*$B$9*$B$10*I6 -> 270 | G6: =E6-F6 -> 54 | I6: 1
A7: CONTRATOS | B7: 15 | D7: 5 | E7: =$B$2*$B$7*$B$8*$B$9*$B$10*I7 -> 648 | F7: =$B$3*$B$7*$B$8*$B$9*$B$10*I7 -> 540 | G7: =E7-F7 -> 108 | I7: 2
A8: ABERT. FECH. | B8: 2 | D8: 6 | E8: =$B$2*$B$7*$B$8*$B$9*$B$10*I8 -> 648 | F8: =$B$3*$B$7*$B$8*$B$9*$B$10*I8 -> 540 | G8: =E8-F8 -> 108 | I8: 2
A9: OPERAÇÕES / DIA | B9: 2 | D9: 7 | E9: =$B$2*$B$7*$B$8*$B$9*$B$10*I9 -> 972 | F9: =$B$3*$B$7*$B$8*$B$9*$B$10*I9 -> 810 | G9: =E9-F9 -> 162 | I9: 3
A10: DIAS OPERADOS | B10: 18 | D10: 8 | E10: =$B$2*$B$7*$B$8*$B$9*$B$10*I10 -> 972 | F10: =$B$3*$B$7*$B$8*$B$9*$B$10*I10 -> 810 | G10: =E10-F10 -> 162 | I10: 3
D11: 9 | E11: =$B$2*$B$7*$B$8*$B$9*$B$10*I11 -> 1296 | F11: =$B$3*$B$7*$B$8*$B$9*$B$10*I11 -> 1080 | G11: =E11-F11 -> 216 | I11: 4
D12: 10 | E12: =$B$2*$B$7*$B$8*$B$9*$B$10*I12 -> 1296 | F12: =$B$3*$B$7*$B$8*$B$9*$B$10*I12 -> 1080 | G12: =E12-F12 -> 216 | I12: 4
D13: 11 | E13: =$B$2*$B$7*$B$8*$B$9*$B$10*I13 -> 1620 | F13: =$B$3*$B$7*$B$8*$B$9*$B$10*I13 -> 1350 | G13: =E13-F13 -> 270 | I13: 5
D14: 12 | E14: =$B$2*$B$7*$B$8*$B$9*$B$10*I14 -> 1620 | F14: =$B$3*$B$7*$B$8*$B$9*$B$10*I14 -> 1350 | G14: =E14-F14 -> 270 | I14: 5
E15: =SUM(E3:E14) -> 9720 | F15: =SUM(F3:F14) -> 8100 | G15: =SUM(G3:G14) -> 1620
A18: ANO 2
A19: Corretagem | B19: 0.3 | D19: MÊS | E19: FATURAMENTO | F19: CUSTO DIRETO | G19: LUCRO LÍQUIDO | I19: CLIENTES
A20: Custo | B20: 0.25 | D20: 1 | E20: =$B$2*$B$7*$B$8*$B$9*$B$10*I20 -> 1620 | F20: =$B$3*$B$7*$B$8*$B$9*$B$10*I20 -> 1350 | G20: =E20-F20 -> 270 | I20: 5
A21: Lucro Bruto | B21: =B19-B20 -> 0.05 | D21: 2 | E21: =$B$2*$B$7*$B$8*$B$9*$B$10*I21 -> 1944 | F21: =$B$3*$B$7*$B$8*$B$9*$B$10*I21 -> 1620 | G21: =E21-F21 -> 324 | I21: 6
A22: TRADERS ATIVOS | B22: 5 | D22: 3 | E22: =$B$2*$B$7*$B$8*$B$9*$B$10*I22 -> 2268 | F22: =$B$3*$B$7*$B$8*$B$9*$B$10*I22 -> 1890 | G22: =E22-F22 -> 378 | I22: 7
D23: 4 | E23: =$B$2*$B$7*$B$8*$B$9*$B$10*I23 -> 2268 | F23: =$B$3*$B$7*$B$8*$B$9*$B$10*I23 -> 1890 | G23: =E23-F23 -> 378 | I23: 7
A24: CONTRATOS | B24: 15 | D24: 5 | E24: =$B$2*$B$7*$B$8*$B$9*$B$10*I24 -> 2592 | F24: =$B$3*$B$7*$B$8*$B$9*$B$10*I24 -> 2160 | G24: =E24-F24 -> 432 | I24: 8
A25: ABERT. FECH. | B25: 2 | D25: 6 | E25: =$B$2*$B$7*$B$8*$B$9*$B$10*I25 -> 2592 | F25: =$B$3*$B$7*$B$8*$B$9*$B$10*I25 -> 2160 | G25: =E25-F25 -> 432 | I25: 8
A26: OPERAÇÕES / DIA | B26: 2 | D26: 7 | E26: =$B$2*$B$7*$B$8*$B$9*$B$10*I26 -> 2916 | F26: =$B$3*$B$7*$B$8*$B$9*$B$10*I26 -> 2430 | G26: =E26-F26 -> 486 | I26: 9
A27: DIAS OPERADOS | B27: 18 | D27: 8 | E27: =$B$2*$B$7*$B$8*$B$9*$B$10*I27 -> 2916 | F27: =$B$3*$B$7*$B$8*$B$9*$B$10*I27 -> 2430 | G27: =E27-F27 -> 486 | I27: 9
D28: 9 | E28: =$B$2*$B$7*$B$8*$B$9*$B$10*I28 -> 3240 | F28: =$B$3*$B$7*$B$8*$B$9*$B$10*I28 -> 2700 | G28: =E28-F28 -> 540 | I28: 10
D29: 10 | E29: =$B$2*$B$7*$B$8*$B$9*$B$10*I29 -> 3240 | F29: =$B$3*$B$7*$B$8*$B$9*$B$10*I29 -> 2700 | G29: =E29-F29 -> 540 | I29: 10
D30: 11 | E30: =$B$2*$B$7*$B$8*$B$9*$B$10*I30 -> 3564 | F30: =$B$3*$B$7*$B$8*$B$9*$B$10*I30 -> 2970 | G30: =E30-F30 -> 594 | I30: 11
D31: 12 | E31: =$B$2*$B$7*$B$8*$B$9*$B$10*I31 -> 3564 | F31: =$B$3*$B$7*$B$8*$B$9*$B$10*I31 -> 2970 | G31: =E31-F31 -> 594 | I31: 11
E32: =SUM(E20:E31) -> 32724 | F32: =SUM(F20:F31) -> 27270 | G32: =SUM(G20:G31) -> 5454
A35: ANO 3
A36: Corretagem | B36: 0.3 | D36: MÊS | E36: FATURAMENTO | F36: CUSTO DIRETO | G36: LUCRO LÍQUIDO | I36: CLIENTES
A37: Custo | B37: 0.25 | D37: 1 | E37: =$B$2*$B$7*$B$8*$B$9*$B$10*I37 -> 3888 | F37: =$B$3*$B$7*$B$8*$B$9*$B$10*I37 -> 3240 | G37: =E37-F37 -> 648 | I37: 12
A38: Lucro Bruto | B38: =B36-B37 -> 0.05 | D38: 2 | E38: =$B$2*$B$7*$B$8*$B$9*$B$10*I38 -> 4212 | F38: =$B$3*$B$7*$B$8*$B$9*$B$10*I38 -> 3510 | G38: =E38-F38 -> 702 | I38: 13
A39: TRADERS ATIVOS | B39: 5 | D39: 3 | E39: =$B$2*$B$7*$B$8*$B$9*$B$10*I39 -> 4536 | F39: =$B$3*$B$7*$B$8*$B$9*$B$10*I39 -> 3780 | G39: =E39-F39 -> 756 | I39: 14
D40: 4 | E40: =$B$2*$B$7*$B$8*$B$9*$B$10*I40 -> 4536 | F40: =$B$3*$B$7*$B$8*$B$9*$B$10*I40 -> 3780 | G40: =E40-F40 -> 756 | I40: 14
A41: CONTRATOS | B41: 15 | D41: 5 | E41: =$B$2*$B$7*$B$8*$B$9*$B$10*I41 -> 4860 | F41: =$B$3*$B$7*$B$8*$B$9*$B$10*I41 -> 4050 | G41: =E41-F41 -> 810 | I41: 15
A42: ABERT. FECH. | B42: 2 | D42: 6 | E42: =$B$2*$B$7*$B$8*$B$9*$B$10*I42 -> 4860 | F42: =$B$3*$B$7*$B$8*$B$9*$B$10*I42 -> 4050 | G42: =E42-F42 -> 810 | I42: 15
A43: OPERAÇÕES / DIA | B43: 2 | D43: 7 | E43: =$B$2*$B$7*$B$8*$B$9*$B$10*I43 -> 5184 | F43: =$B$3*$B$7*$B$8*$B$9*$B$10*I43 -> 4320 | G43: =E43-F43 -> 864 | I43: 16
A44: DIAS OPERADOS | B44: 18 | D44: 8 | E44: =$B$2*$B$7*$B$8*$B$9*$B$10*I44 -> 5184 | F44: =$B$3*$B$7*$B$8*$B$9*$B$10*I44 -> 4320 | G44: =E44-F44 -> 864 | I44: 16
...

Sheet TRADERS FOCO
A1: ANO 1
A2: 1 SALÁRIO MÍNIMO | B2: 1320 | D2: MÊS | E2: FATURAMENTO | F2: CUSTO DIRETO | G2: LUCRO LÍQUIDO | I2: CLIENTES
A3: CUSTO IR | B3: =B2*0.2 -> 264 | D3: 1 | E3: =$B$2*I3 -> 0 | F3: =($B$3+$B$7)*I3 -> 0 | G3: =E3-F3 -> 0 | I3: 0
A4: VALOR LÍQUIDO | B4: =B2-B3 -> 1056 | D4: 2 | E4: =$B$2*I4 -> 0 | F4: =($B$3+$B$7)*I4 -> 0 | G4: =E4-F4 -> 0 | I4: 0
A5: TRADERS ATIVOS | B5: 5 | D5: 3 | E5: =$B$2*I5 -> 1320 | F5: =($B$3+$B$7)*I5 -> 1214.4 | G5: =E5-F5 -> 105.6 | I5: 1
D6: 4 | E6: =$B$2*I6 -> 1320 | F6: =($B$3+$B$7)*I6 -> 1214.4 | G6: =E6-F6 -> 105.6 | I6: 1
A7: REPASSE 90% | B7: =B4*0.9 -> 950.4 | D7: 5 | E7: =$B$2*I7 -> 2640 | F7: =($B$3+$B$7)*I7 -> 2428.8 | G7: =E7-F7 -> 211.2 | I7: 2
A8: MESA 10% | B8: =B4*0.1 -> 105.6 | D8: 6 | E8: =$B$2*I8 -> 2640 | F8: =($B$3+$B$7)*I8 -> 2428.8 | G8: =E8-F8 -> 211.2 | I8: 2
D9: 7 | E9: =$B$2*I9 -> 3960 | F9: =($B$3+$B$7)*I9 -> 3643.2 | G9: =E9-F9 -> 316.8 | I9: 3
D10: 8 | E10: =$B$2*I10 -> 3960 | F10: =($B$3+$B$7)*I10 -> 3643.2 | G10: =E10-F10 -> 316.8 | I10: 3
D11: 9 | E11: =$B$2*I11 -> 5280 | F11: =($B$3+$B$7)*I11 -> 4857.6 | G11: =E11-F11 -> 422.4 | I11: 4
D12: 10 | E12: =$B$2*I12 -> 5280 | F12: =($B$3+$B$7)*I12 -> 4857.6 | G12: =E12-F12 -> 422.4 | I12: 4
D13: 11 | E13: =$B$2*I13 -> 6600 | F13: =($B$3+$B$7)*I13 -> 6072 | G13: =E13-F13 -> 528 | I13: 5
D14: 12 | E14: =$B$2*I14 -> 6600 | F14: =($B$3+$B$7)*I14 -> 6072 | G14: =E14-F14 -> 528 | I14: 5
E15: =SUM(E3:E14) -> 39600 | F15: =SUM(F3:F14) -> 36432 | G15: =SUM(G3:G14) -> 3168
A18: ANO 2
A19: 1 SALÁRIO MÍNIMO | B19: 1320 | D19: MÊS | E19: FATURAMENTO | F19: CUSTO DIRETO | G19: LUCRO LÍQUIDO | I19: CLIENTES
A20: CUSTO IR | B20: =B19*0.2 -> 264 | D20: 1 | E20: =$B$19*I20 -> 6600 | F20: =($B$20+$B$24)*I20 -> 6072 | G20: =E20-F20 -> 528 | I20: 5
A21: VALOR LÍQUIDO | B21: =B19-B20 -> 1056 | D21: 2 | E21: =$B$19*I21 -> 7920 | F21: =($B$20+$B$24)*I21 -> 7286.4 | G21: =E21-F21 -> 633.6 | I21: 6
A22: TRADERS ATIVOS | B22: 11 | D22: 3 | E22: =$B$19*I22 -> 9240 | F22: =($B$20+$B$24)*I22 -> 8500.8 | G22: =E22-F22 -> 739.2 | I22: 7
D23: 4 | E23: =$B$19*I23 -> 9240 | F23: =($B$20+$B$24)*I23 -> 8500.8 | G23: =E23-F23 -> 739.2 | I23: 7
A24: REPASSE 90% | B24: =B21*0.9 -> 950.4 | D24: 5 | E24: =$B$19*I24 -> 10560 | F24: =($B$20+$B$24)*I24 -> 9715.2 | G24: =E24-F24 -> 844.8 | I24: 8
A25: MESA 10% | B25: =B21*0.1 -> 105.6 | D25: 6 | E25: =$B$19*I25 -> 10560 | F25: =($B$20+$B$24)*I25 -> 9715.2 | G25: =E25-F25 -> 844.8 | I25: 8
D26: 7 | E26: =$B$19*I26 -> 11880 | F26: =($B$20+$B$24)*I26 -> 10929.6 | G26: =E26-F26 -> 950.4 | I26: 9
D27: 8 | E27: =$B$19*I27 -> 11880 | F27: =($B$20+$B$24)*I27 -> 10929.6 | G27: =E27-F27 -> 950.4 | I27: 9
D28: 9 | E28: =$B$19*I28 -> 13200 | F28: =($B$20+$B$24)*I28 -> 12144 | G28: =E28-F28 -> 1056 | I28: 10
D29: 10 | E29: =$B$19*I29 -> 13200 | F29: =($B$20+$B$24)*I29 -> 12144 | G29: =E29-F29 -> 1056 | I29: 10
D30: 11 | E30: =$B$19*I30 -> 14520 | F30: =($B$20+$B$24)*I30 -> 13358.4 | G30: =E30-F30 -> 1161.6 | I30: 11
D31: 12 | E31: =$B$19*I31 -> 14520 | F31: =($B$20+$B$24)*I31 -> 13358.4 | G31: =E31-F31 -> 1161.6 | I31: 11
E32: =SUM(E20:E31) -> 133320 | F32: =SUM(F20:F31) -> 122654.4 | G32: =SUM(G20:G31) -> 10665.6
A35: ANO 3
A36: 1 SALÁRIO MÍNIMO | B36: 1320 | D36: MÊS | E36: FATURAMENTO | F36: CUSTO DIRETO | G36: LUCRO LÍQUIDO | I36: CLIENTES
A37: CUSTO IR | B37: =B36*0.2 -> 264 | D37: 1 | E37: =$B$36*I37 -> 15840 | F37: =($B$37+$B$41)*I37 -> 14572.8 | G37: =E37-F37 -> 1267.2 | I37: 12
A38: VALOR LÍQUIDO | B38: =B36-B37 -> 1056 | D38: 2 | E38: =$B$36*I38 -> 17160 | F38: =($B$37+$B$41)*I38 -> 15787.2 | G38: =E38-F38 -> 1372.8 | I38: 13
A39: TRADERS ATIVOS | B39: 18 | D39: 3 | E39: =$B$36*I39 -> 18480 | F39: =($B$37+$B$41)*I39 -> 17001.6 | G39: =E39-F39 -> 1478.4 | I39: 14
D40: 4 | E40: =$B$36*I40 -> 18480 | F40: =($B$37+$B$41)*I40 -> 17001.6 | G40: =E40-F40 -> 1478.4 | I40: 14
A41: REPASSE 90% | B41: =B38*0.9 -> 950.4 | D41: 5 | E41: =$B$36*I41 -> 19800 | F41: =($B$37+$B$41)*I41 -> 18216 | G41: =E41-F41 -> 1584 | I41: 15
A42: MESA 10% | B42: =B38*0.1 -> 105.6 | D42: 6 | E42: =$B$36*I42 -> 19800 | F42: =($B$37+$B$41)*I42 -> 18216 | G42: =E42-F42 -> 1584 | I42: 15
D43: 7 | E43: =$B$36*I43 -> 21120 | F43: =($B$37+$B$41)*I43 -> 19430.4 | G43: =E43-F43 -> 1689.6 | I43: 16
D44: 8 | E44: =$B$36*I44 -> 21120 | F44: =($B$37+$B$41)*I44 -> 19430.4 | G44: =E44-F44 -> 1689.6 | I44: 16
...

Sheet PROJEÇÕES
B1: ANO 1
A2: RECEITAS | B2: FATURAMENTO | C2: CUSTO DIRETO | D2: IMPOSTO | E2: LUCRO LÍQUIDO
A3: EXAMES | B3: =EXAMES!E15 -> 49700 | C3: =EXAMES!F15 -> 37490 | D3: =EXAMES!G15 -> 4970 | E3: =EXAMES!H15 -> 7240
A4: PLATAFORMAS | B4: =PLATAFORMAS!E15 -> 2970 | C4: =PLATAFORMAS!F15 -> 2697 | D4: 0 | E4: =PLATAFORMAS!G15 -> 273
A5: CORRETAGEM | B5: =CORRETAGEM!E15 -> 9720 | C5: =CORRETAGEM!F15 -> 8100 | D5: 0 | E5: =CORRETAGEM!G15 -> 1620
A6: TRADERS XS | B6: ='TRADERS FOCO'!E15 -> 39600 | C6: ='TRADERS FOCO'!F15 -> 36432 | D6: 0 | E6: ='TRADERS FOCO'!G15 -> 3168
B7: =SUM(B3:B6) -> 101990 | C7: =SUM(C3:C6) -> 84719 | D7: =SUM(D3:D6) -> 4970 | E7: =SUM(E3:E6) -> 12301
B10: ANO 2
A11: RECEITAS | B11: FATURAMENTO | C11: CUSTO DIRETO | D11: IMPOSTO | E11: LUCRO LÍQUIDO
A12: EXAMES | B12: =EXAMES!E32 -> 59640 | C12: =EXAMES!F32 -> 44988 | D12: =EXAMES!G32 -> 5964 | E12: =EXAMES!H32 -> 8688
A13: PLATAFORMAS | B13: =PLATAFORMAS!E32 -> 9999 | C13: =PLATAFORMAS!F32 -> 9079.9 | D13: 0 | E13: =PLATAFORMAS!G32 -> 919.1
A14: CORRETAGEM | B14: =CORRETAGEM!E32 -> 32724 | C14: =CORRETAGEM!F32 -> 27270 | D14: 0 | E14: =CORRETAGEM!G32 -> 5454
A15: TRADERS XS | B15: ='TRADERS FOCO'!E32 -> 133320 | C15: ='TRADERS FOCO'!F32 -> 122654.4 | D15: 0 | E15: ='TRADERS FOCO'!G32 -> 10665.6
B16: =SUM(B12:B15) -> 235683 | C16: =SUM(C12:C15) -> 203992.3 | D16: =SUM(D12:D15) -> 5964 | E16: =SUM(E12:E15) -> 25726.7
B19: ANO 3
A20: RECEITAS | B20: FATURAMENTO | C20: CUSTO DIRETO | D20: IMPOSTO | E20: LUCRO LÍQUIDO
A21: EXAMES | B21: =EXAMES!E49 -> 71568 | C21: =EXAMES!F49 -> 52845.6 | D21: =EXAMES!G49 -> 7156.8 | E21: =EXAMES!H49 -> 11565.6
A22: PLATAFORMAS | B22: =PLATAFORMAS!E49 -> 18315 | C22: =PLATAFORMAS!F49 -> 16631.5 | D22: 0 | E22: =PLATAFORMAS!G49 -> 1683.5
A23: CORRETAGEM | B23: =CORRETAGEM!E49 -> 59940 | C23: =CORRETAGEM!F49 -> 49950 | D23: 0 | E23: =CORRETAGEM!G49 -> 9990
A24: TRADERS XS | B24: ='TRADERS FOCO'!E49 -> 244200 | C24: ='TRADERS FOCO'!F49 -> 224664 | D24: 0 | E24: ='TRADERS FOCO'!G49 -> 19536
B25: =SUM(B21:B24) -> 394023 | C25: =SUM(C21:C24) -> 344091.1 | D25: =SUM(D21:D24) -> 7156.8 | E25: =SUM(E21:E24) -> 42775.1
B28: ANO | C28: FATURAMENTO | D28: CUSTO DIRETO | E28: IMPOSTO | F28: LUCRO LÍQUIDO
B29: 1 | C29: =B7 -> 101990 | D29: =C7 -> 84719 | E29: =D7 -> 4970 | F29: =E7 -> 12301
B30: 2 | C30: =B16 -> 235683 | D30: =C16 -> 203992.3 | E30: =D16 -> 5964 | F30: =E16 -> 25726.7
B31: 3 | C31: =B25 -> 394023 | D31: =C25 -> 344091.1 | E31: =D25 -> 7156.8 | F31: =E25 -> 42775.1
C32: =SUM(C29:C31) -> 731696 | D32: =SUM(D29:D31) -> 632802.4 | E32: =SUM(E29:E31) -> 18090.8 | F32: =SUM(F29:F31) -> 80802.8
